[2025-06-19T10:56:49.584+0000] {taskinstance.py:1969} INFO - Dependencies not met for <TaskInstance: lung_cancer_ml_pipeline.train_model_task manual__2025-06-19T16:41:41+05:45 [up_for_retry]>, dependency 'Not In Retry Period' FAILED: Task is not ready for retry yet but will be retried automatically. Current date is 2025-06-19T10:56:49.584091+00:00 and task will be retried at 2025-06-19T11:01:49.429872+00:00.
[2025-06-19T10:56:49.620+0000] {local_task_job_runner.py:160} INFO - Task is not able to be run
[2025-06-19T11:06:22.161+0000] {taskinstance.py:1979} INFO - Dependencies all met for dep_context=non-requeueable deps ti=<TaskInstance: lung_cancer_ml_pipeline.train_model_task manual__2025-06-19T16:41:41+05:45 [queued]>
[2025-06-19T11:06:22.167+0000] {taskinstance.py:1979} INFO - Dependencies all met for dep_context=requeueable deps ti=<TaskInstance: lung_cancer_ml_pipeline.train_model_task manual__2025-06-19T16:41:41+05:45 [queued]>
[2025-06-19T11:06:22.167+0000] {taskinstance.py:2193} INFO - Starting attempt 2 of 2
[2025-06-19T11:06:22.204+0000] {taskinstance.py:2214} INFO - Executing <Task(PythonOperator): train_model_task> on 2025-06-19 10:56:41+00:00
[2025-06-19T11:06:22.212+0000] {standard_task_runner.py:60} INFO - Started process 137 to run task
[2025-06-19T11:06:22.214+0000] {standard_task_runner.py:87} INFO - Running: ['***', 'tasks', 'run', 'lung_cancer_ml_pipeline', 'train_model_task', 'manual__2025-06-19T16:41:41+05:45', '--job-id', '60', '--raw', '--subdir', 'DAGS_FOLDER/ml_pipeline_dag.py', '--cfg-path', '/tmp/tmpargcgbe2']
[2025-06-19T11:06:22.216+0000] {standard_task_runner.py:88} INFO - Job 60: Subtask train_model_task
[2025-06-19T11:06:22.247+0000] {warnings.py:109} WARNING - /home/***/.local/lib/python3.8/site-packages/***/settings.py:194: DeprecationWarning: The sql_alchemy_conn option in [core] has been moved to the sql_alchemy_conn option in [database] - the old setting has been used, but please update your config.
  SQL_ALCHEMY_CONN = conf.get("database", "SQL_ALCHEMY_CONN")

[2025-06-19T11:06:22.274+0000] {task_command.py:423} INFO - Running <TaskInstance: lung_cancer_ml_pipeline.train_model_task manual__2025-06-19T16:41:41+05:45 [running]> on host 0064cba90111
[2025-06-19T11:06:22.366+0000] {taskinstance.py:2510} INFO - Exporting env vars: AIRFLOW_CTX_DAG_OWNER='***' AIRFLOW_CTX_DAG_ID='lung_cancer_ml_pipeline' AIRFLOW_CTX_TASK_ID='train_model_task' AIRFLOW_CTX_EXECUTION_DATE='2025-06-19T10:56:41+00:00' AIRFLOW_CTX_TRY_NUMBER='2' AIRFLOW_CTX_DAG_RUN_ID='manual__2025-06-19T16:41:41+05:45'
[2025-06-19T11:06:22.367+0000] {logging_mixin.py:188} INFO - Starting model training task...
[2025-06-19T11:06:22.393+0000] {logging_mixin.py:188} INFO - Retrieved DataFrame with shape (1000, 21) from key 'lung_cancer:model_features'
[2025-06-19T11:06:22.421+0000] {logging_mixin.py:188} INFO - Using existing experiment 'lung_cancer_mortality_prediction' with ID: 1
[2025-06-19T11:06:22.466+0000] {logging_mixin.py:188} WARNING - 2025/06/19 11:06:22 WARNING mlflow.utils.git_utils: Failed to import Git (the Git executable is probably not on your PATH), so Git SHA is not available. Error: Failed to initialize: Bad git executable.
The git executable must be specified in one of the following ways:
    - be included in your $PATH
    - be set via $GIT_PYTHON_GIT_EXECUTABLE
    - explicitly set via git.refresh(<full-path-to-git-executable>)

All git commands will error until this is rectified.

This initial message can be silenced or aggravated in the future by setting the
$GIT_PYTHON_REFRESH environment variable. Use one of the following values:
    - quiet|q|silence|s|silent|none|n|0: for no message or exception
    - warn|w|warning|log|l|1: for a warning message (logging level CRITICAL, displayed by default)
    - error|e|exception|raise|r|2: for a raised exception

Example:
    export GIT_PYTHON_REFRESH=quiet
[2025-06-19T11:06:22.492+0000] {logging_mixin.py:188} INFO - Started MLflow run: training_run
[2025-06-19T11:06:22.509+0000] {logging_mixin.py:188} INFO - Splitting data into training and testing sets...
[2025-06-19T11:06:22.517+0000] {logging_mixin.py:188} INFO - Training set: 800 samples
[2025-06-19T11:06:22.518+0000] {logging_mixin.py:188} INFO - Testing set: 200 samples
[2025-06-19T11:06:22.518+0000] {logging_mixin.py:188} INFO - Starting model training process...
[2025-06-19T11:06:22.523+0000] {logging_mixin.py:188} INFO - Target variable appears to be continuous. Using regression model instead of classifier.
[2025-06-19T11:06:22.523+0000] {logging_mixin.py:188} INFO - Training RandomForestRegressor model...
[2025-06-19T11:06:23.038+0000] {logging_mixin.py:188} INFO - Model saved to: /opt/***/models/randomforestregressor_model.joblib
[2025-06-19T11:06:23.039+0000] {logging_mixin.py:188} INFO - Model training completed
[2025-06-19T11:06:23.055+0000] {logging_mixin.py:188} INFO - Logged 3 parameters
[2025-06-19T11:06:24.723+0000] {logging_mixin.py:188} WARNING - 2025/06/19 11:06:24 WARNING mlflow.models.model: Model logged without a signature and input example. Please set `input_example` parameter when logging the model to auto infer the model signature.
[2025-06-19T11:06:24.740+0000] {taskinstance.py:2728} ERROR - Task failed with exception
Traceback (most recent call last):
  File "/home/airflow/.local/lib/python3.8/site-packages/airflow/models/taskinstance.py", line 444, in _execute_task
    result = _execute_callable(context=context, **execute_callable_kwargs)
  File "/home/airflow/.local/lib/python3.8/site-packages/airflow/models/taskinstance.py", line 414, in _execute_callable
    return execute_callable(context=context, **execute_callable_kwargs)
  File "/home/airflow/.local/lib/python3.8/site-packages/airflow/operators/python.py", line 200, in execute
    return_value = self.execute_callable()
  File "/home/airflow/.local/lib/python3.8/site-packages/airflow/operators/python.py", line 217, in execute_callable
    return self.python_callable(*self.op_args, **self.op_kwargs)
  File "/opt/airflow/dags/ml_pipeline_dag.py", line 199, in train_model_task
    mlflow_tracker.log_model(model)
  File "/opt/airflow/src/utils/mlflow_utils.py", line 106, in log_model
    mlflow.sklearn.log_model(
  File "/home/airflow/.local/lib/python3.8/site-packages/mlflow/sklearn/__init__.py", line 413, in log_model
    return Model.log(
  File "/home/airflow/.local/lib/python3.8/site-packages/mlflow/models/model.py", line 744, in log
    mlflow.tracking.fluent.log_artifacts(local_path, mlflow_model.artifact_path, run_id)
  File "/home/airflow/.local/lib/python3.8/site-packages/mlflow/tracking/fluent.py", line 1170, in log_artifacts
    MlflowClient().log_artifacts(run_id, local_dir, artifact_path)
  File "/home/airflow/.local/lib/python3.8/site-packages/mlflow/tracking/client.py", line 1977, in log_artifacts
    self._tracking_client.log_artifacts(run_id, local_dir, artifact_path)
  File "/home/airflow/.local/lib/python3.8/site-packages/mlflow/tracking/_tracking_service/client.py", line 874, in log_artifacts
    self._get_artifact_repo(run_id).log_artifacts(local_dir, artifact_path)
  File "/home/airflow/.local/lib/python3.8/site-packages/mlflow/store/artifact/local_artifact_repo.py", line 66, in log_artifacts
    mkdir(artifact_dir)
  File "/home/airflow/.local/lib/python3.8/site-packages/mlflow/utils/file_utils.py", line 211, in mkdir
    raise e
  File "/home/airflow/.local/lib/python3.8/site-packages/mlflow/utils/file_utils.py", line 208, in mkdir
    os.makedirs(target, exist_ok=True)
  File "/usr/local/lib/python3.8/os.py", line 213, in makedirs
    makedirs(head, exist_ok=exist_ok)
  File "/usr/local/lib/python3.8/os.py", line 213, in makedirs
    makedirs(head, exist_ok=exist_ok)
  File "/usr/local/lib/python3.8/os.py", line 213, in makedirs
    makedirs(head, exist_ok=exist_ok)
  [Previous line repeated 2 more times]
  File "/usr/local/lib/python3.8/os.py", line 223, in makedirs
    mkdir(name, mode)
PermissionError: [Errno 13] Permission denied: '/mlflow'
[2025-06-19T11:06:24.749+0000] {taskinstance.py:1149} INFO - Marking task as FAILED. dag_id=lung_cancer_ml_pipeline, task_id=train_model_task, execution_date=20250619T105641, start_date=20250619T110622, end_date=20250619T110624
[2025-06-19T11:06:24.857+0000] {standard_task_runner.py:107} ERROR - Failed to execute job 60 for task train_model_task ([Errno 13] Permission denied: '/mlflow'; 137)
[2025-06-19T11:06:24.896+0000] {local_task_job_runner.py:234} INFO - Task exited with return code 1
[2025-06-19T11:06:24.914+0000] {taskinstance.py:3309} INFO - 0 downstream tasks scheduled from follow-on schedule check
