[2025-06-19T10:25:56.634+0000] {taskinstance.py:1979} INFO - Dependencies all met for dep_context=non-requeueable deps ti=<TaskInstance: lung_cancer_ml_pipeline.transform_data_task manual__2025-06-19T10:25:48+00:00 [queued]>
[2025-06-19T10:25:56.641+0000] {taskinstance.py:1979} INFO - Dependencies all met for dep_context=requeueable deps ti=<TaskInstance: lung_cancer_ml_pipeline.transform_data_task manual__2025-06-19T10:25:48+00:00 [queued]>
[2025-06-19T10:25:56.642+0000] {taskinstance.py:2193} INFO - Starting attempt 1 of 2
[2025-06-19T10:25:56.672+0000] {taskinstance.py:2214} INFO - Executing <Task(PythonOperator): transform_data_task> on 2025-06-19 10:25:48+00:00
[2025-06-19T10:25:56.680+0000] {standard_task_runner.py:60} INFO - Started process 228 to run task
[2025-06-19T10:25:56.684+0000] {standard_task_runner.py:87} INFO - Running: ['***', 'tasks', 'run', 'lung_cancer_ml_pipeline', 'transform_data_task', 'manual__2025-06-19T10:25:48+00:00', '--job-id', '9', '--raw', '--subdir', 'DAGS_FOLDER/ml_pipeline_dag.py', '--cfg-path', '/tmp/tmpzznrfw4n']
[2025-06-19T10:25:56.686+0000] {standard_task_runner.py:88} INFO - Job 9: Subtask transform_data_task
[2025-06-19T10:25:56.726+0000] {warnings.py:109} WARNING - /home/***/.local/lib/python3.8/site-packages/***/settings.py:194: DeprecationWarning: The sql_alchemy_conn option in [core] has been moved to the sql_alchemy_conn option in [database] - the old setting has been used, but please update your config.
  SQL_ALCHEMY_CONN = conf.get("database", "SQL_ALCHEMY_CONN")

[2025-06-19T10:25:56.752+0000] {task_command.py:423} INFO - Running <TaskInstance: lung_cancer_ml_pipeline.transform_data_task manual__2025-06-19T10:25:48+00:00 [running]> on host 50ee7aa98663
[2025-06-19T10:25:56.843+0000] {taskinstance.py:2510} INFO - Exporting env vars: AIRFLOW_CTX_DAG_OWNER='***' AIRFLOW_CTX_DAG_ID='lung_cancer_ml_pipeline' AIRFLOW_CTX_TASK_ID='transform_data_task' AIRFLOW_CTX_EXECUTION_DATE='2025-06-19T10:25:48+00:00' AIRFLOW_CTX_TRY_NUMBER='1' AIRFLOW_CTX_DAG_RUN_ID='manual__2025-06-19T10:25:48+00:00'
[2025-06-19T10:25:56.844+0000] {logging_mixin.py:188} INFO - Starting data transformation task...
[2025-06-19T10:25:56.852+0000] {logging_mixin.py:188} INFO - Error retrieving DataFrame from Redis: Expected file path name or file-like object, got <class 'bytes'> type
[2025-06-19T10:25:56.853+0000] {taskinstance.py:2728} ERROR - Task failed with exception
Traceback (most recent call last):
  File "/home/airflow/.local/lib/python3.8/site-packages/airflow/models/taskinstance.py", line 444, in _execute_task
    result = _execute_callable(context=context, **execute_callable_kwargs)
  File "/home/airflow/.local/lib/python3.8/site-packages/airflow/models/taskinstance.py", line 414, in _execute_callable
    return execute_callable(context=context, **execute_callable_kwargs)
  File "/home/airflow/.local/lib/python3.8/site-packages/airflow/operators/python.py", line 200, in execute
    return_value = self.execute_callable()
  File "/home/airflow/.local/lib/python3.8/site-packages/airflow/operators/python.py", line 217, in execute_callable
    return self.python_callable(*self.op_args, **self.op_kwargs)
  File "/opt/airflow/dags/ml_pipeline_dag.py", line 96, in transform_data_task
    raise ValueError("Cleaned data not found in Redis")
ValueError: Cleaned data not found in Redis
[2025-06-19T10:25:56.860+0000] {taskinstance.py:1149} INFO - Marking task as UP_FOR_RETRY. dag_id=lung_cancer_ml_pipeline, task_id=transform_data_task, execution_date=20250619T102548, start_date=20250619T102556, end_date=20250619T102556
[2025-06-19T10:25:56.894+0000] {standard_task_runner.py:107} ERROR - Failed to execute job 9 for task transform_data_task (Cleaned data not found in Redis; 228)
[2025-06-19T10:25:56.944+0000] {local_task_job_runner.py:234} INFO - Task exited with return code 1
[2025-06-19T10:25:56.963+0000] {taskinstance.py:3309} INFO - 0 downstream tasks scheduled from follow-on schedule check
